Workbook

Sheet RawData
B1: REV | C1: REV Grow | D1: Rev 5YR CAGR | E1: EPS | F1: EPS Grow | G1: NI 5YR CAGR | H1: GM | I1: SG&A 2 REV | J1: EBITDA % | K1: OPMargin | L1: DEG OF OP LEV | M1: FCF | N1: FCF Grow | O1: INVEN TURN | P1: CAPEX 2 REV | Q1: R&D | R1: R&D / REV | S1: CASH | T1: CASH / ASSET | U1: NET DEBT | V1: N DEBT/EQUITY | W1: ROA | X1: ROE | Y1: CROCI | Z1: PE | AA1: Forward PE | AB1: P/S | AC1: P/B | AD1: EV/EBITDA | AE1: EV/FCF | AF1: DIVIDEND | AG1: MKT CAP | AH1: EV | AI1: SHARE $ | AJ1: Shares Out | AK1: EBITDA | AL1: EBITDA Growth | AM1: EBTIDA 5yr CAGR
A2: EUSP | B2: No data | C2: -0.56 | D2: 0.045778085 | E2: -0.091298684 | F2: -20.9459 | G2: No data | H2: 0.2963 | I2: 0 | J2: -2.1912167 | K2: No data | L2: No data | M2: 3.96015 | N2: 2.8110893 | O2: No data | P2: 0.0017576141 | Q2: 0.72726 | R2: No data | S2: No data | T2: 0.9741707 | U2: No data | V2: -0.9794 | W2: -0.8302 | X2: No data | Y2: No data | AA2: No data | AB2: 1.2801472 | AC2: No data | AD2: 0.30796728 | AE2: -0.558441 | AF2: No data | AG2: 4.19544 | AH2: -2.21151 | AI2: 0.051 | AJ2: 82.26 | AK2: -7.18099 | AL2: No data | AM2: 0.32108018
A3: GNE | C3: 0.1312 | D3: 0.06155537 | E3: 0.18308796 | F3: 0.41564506 | H3: 0.2572 | I3: 0.18829301 | J3: 0.0038859139 | M3: 34.961 | N3: 0.6393161 | P3: 0.017451437 | Q3: No data | S3: No data | T3: 0.27727455 | V3: -0.506248 | W3: 0.0127 | Z3: 79.08767 | AA3: 24.905401 | AB3: 0.7936849 | AD3: 150.76901 | AE3: 8.098859 | AG3: 377.5485 | AH3: 283.1442 | AI3: 14.48 | AJ3: 26.49 | AK3: 1.878 | AM3: -0.4143127
A4: ENG | C4: -0.3871 | D4: -0.13786851 | E4: -1.3306202 | F4: -0.6921076 | H4: 0.0676 | I4: 0.33289343 | J4: -0.22335532 | M4: -1.679 | N4: 0.16113244 | P4: 0.004239152 | Q4: No data | S4: No data | T4: 0.09304611 | V4: -0.32514092 | W4: -0.4368 | AA4: 1.0699426 | AB4: 0.09278145 | AD4: -0.67358994 | AE4: -2.2406194 | AG4: 2.32 | AH4: 3.762 | AI4: No data | AJ4: 5.16 | AK4: -5.585 | AM4: 0.019537123
A5: WAVE | C5: 0.2645 | D5: No data | E5: -0.3556507 | F5: No data | H5: 0.75 | I5: 12.327381 | J5: -12.755953 | M5: 0 | N5: No data | P5: No data | Q5: 0.359 | S5: No data | T5: 0.614155 | V5: -0.7908 | W5: -0.2247 | AB5: 205.09525 | AD5: -13.758749 | AG5: 34.82723 | AH5: 29.485 | AI5: 5.9 | AJ5: 5.84 | AK5: -2.143 | AM5: No data
A6: GAME | C6: -0.4248 | D6: -0.12822299 | E6: -0.31139722 | F6: -0.46814975 | H6: 0.1917 | I6: 0.38631046 | J6: -0.48854575 | M6: -22.84184 | N6: 0.720281 | P6: 0.00525471 | Q6: 2.7225 | S6: 6.01222 | T6: 0.049638845 | V6: -0.0764 | W6: -0.3931 | AB6: 0.633634 | AD6: -1.1254569 | AE6: -1.7270608 | AG6: 46.263557 | AH6: 39.449177 | AI6: 0.4621 | AJ6: 98.38 | AK6: -35.05172 | AM6: -0.15716498
A7: PI | C7: 0.0424 | D7: 0.20215866 | E7: -0.4117569 | F7: -1.2009693 | H7: 0.5221 | I7: 0.23744632 | J7: 0.020047527 | M7: 40.267 | N7: 0.3955268 | P7: 0.042643726 | Q7: 101.58 | S7: No data | T7: 0.10015509 | V7: 1.1727 | W7: -0.0249 | AA7: 86.15877 | AB7: 15.177392 | AD7: 788.76843 | AE7: 141.29155 | AG7: 6404.815 | AH7: 5689.3867 | AI7: 181.36 | AJ7: 30.11 | AK7: 7.213 | AM7: -0.030969055
A8: IDT | C8: 0.0252 | D8: -0.015953567 | E8: 3.2392502 | F8: 0.096753284 | H8: 0.367 | I8: 0.2334118 | J8: 0.10358164 | M8: 92.905 | N8: 2.1266053 | P8: 0.017123276 | Q8: 51.836 | S8: No data | T8: 0.2890048 | V8: -0.5902 | W8: 0.1322 | Z8: 16.068533 | AA8: 15.501221 | AB8: 1.0483767 | AD8: 8.653185 | AE8: 12.008185 | AG8: 1272.4558 | AH8: 1115.6205 | AI8: 52.05 | AJ8: 25.07 | AK8: 128.926 | AM8: 0.19638498
A9: BKTI | C9: 0.0463 | D9: 0.1438503 | E9: 3.1868632 | F9: 3.362202 | H9: 0.4366 | I9: 0.25739858 | J9: 0.1696627 | M9: 12.283 | N9: 8.8942795 | P9: 0.029134642 | Q9: 2.306 | S9: No data | T9: 0.19615728 | V9: -0.3224 | W9: 0.2218 | Z9: 27.447052 | AA9: 21.765203 | AB9: 4.1654506 | AD9: 23.659426 | AE9: 25.597176 | AG9: 288.68884 | AH9: 314.4101 | AI9: 87.47 | AJ9: 3.73 | AK9: 13.289 | AM9: 0.74884135
A10: RDVT | C10: 0.2227 | D10: 0.2003615 | E10: 0.79503196 | F10: 1.2094674 | H10: 0.835 | I10: 0.5771015 | J10: 0.2579462 | M10: 18.936 | N10: 1.5683286 | P10: 0.12050911 | Q10: No data | S10: No data | T10: 0.40467203 | V10: -0.4458 | W10: 0.1081 | Z10: 63.98485 | AA10: 43.60722 | AB10: 8.293414 | AD10: 30.11736 | AE10: 35.456608 | AG10: 745.3378 | AH10: 671.4063 | AI10: 50.87 | AJ10: 14.09 | AK10: 22.293 | AM10: No data
A11: INOD | C11: 0.7357 | D11: 0.3285289 | E11: 1.055995 | F11: 0.68085533 | H11: 0.4132 | I11: 0.24464601 | J11: 0.19577551 | M11: 40.697 | N11: 3.68933 | P11: 0.044052217 | Q11: No data | S11: No data | T11: 0.48300374 | V11: -0.6696978 | W11: 0.2567 | Z11: 59.81089 | AA11: 70.241 | AB11: 8.43839 | AD11: 41.706306 | AE11: 47.843838 | AG11: 2107.9204 | AH11: 1947.1006 | AI11: 63.16 | AJ11: 31.86 | AK11: 46.686 | AM11: 0.7872666
A12: EACO | C12: 0.1631 | D12: 0.12024409 | E12: 6.1020575 | F12: 1.0429871 | H12: 0.3011 | I12: 0.20105627 | J12: 0.10431313 | M12: 18.429 | N12: -0.7756313 | P12: 0.0016393769 | Q12: No data | S12: No data | T12: 0.01653093 | V12: 0.0077 | W12: 0.1472 | Z12: 13.929728 | AB12: 1.027658 | AD12: 9.878493 | AE12: 22.476803 | AG12: 413.23517 | AH12: 414.225 | AI12: 85 | AJ12: 4.86 | AK12: 41.932 | AM12: 0.25658518
A13: IIIV | C13: -0.2369 | D13: 0.0904248 | E13: 0.5524884 | F13: -0.8439366 | H13: 0.6647 | I13: 0.5156077 | J13: 0.17667738 | M13: -4.441 | N13: -0.13457575 | P13: 0.043769866 | Q13: No data | S13: No data | T13: 0.10443429 | V13: -0.1711 | W13: 0.0271 | Z13: 48.906002 | AA13: 23.408056 | AB13: 3.774949 | AD13: 19.736616 | AE13: -181.81152 | AG13: 884.8759 | AH13: 807.425 | AI13: 27.02 | AJ13: 32.35 | AK13: 40.91 | AM13: 0.11801729
A14: GLAE | C14: 1 | D14: 0.14869836 | E14: -133.33333 | F14: -1.2 | H14: 1 | I14: 20 | J14: No data | M14: -3.4 | N14: 0.8292683 | P14: No data | Q14: No data | S14: No data | T14: 0.13304721 | V14: 2.069 | W14: -0.2439 | AB14: 4.2 | AE14: -3.7764707 | AG14: 0.7 | AH14: 12.84 | AI14: 28 | AJ14: 0.03 | AK14: No data | AM14: No data
A15: FC | C15: -0.0899 | D15: 0.061245136 | E15: 0.25230262 | F15: -0.8689001 | H15: 0.7604 | I15: 0.68404186 | J15: 0.05302789 | M15: 13.163 | N15: 0.26486507 | P15: 0.059213605 | Q15: No data | S15: No data | T15: 0.1304917 | V15: -0.46143386 | W15: -0.0062 | Z15: 78.952805 | AA15: 58.008152 | AB15: 0.9069904 | AD15: 14.923895 | AE15: 16.056538 | AG15: 225.53098 | AH15: 211.3522 | AI15: 19.92 | AJ15: 12.16 | AK15: 14.162 | AM15: -0.0015182684
A16: AVNW | C16: 0.1089 | D16: 0.12976143 | E16: 1.0422119 | F16: -3.6116316 | H16: 0.3425 | I16: 0.19384913 | J16: 0.08916928 | M16: 11.868 | N16: -0.17378317 | P16: 0.02045438 | Q16: 32.458 | S16: No data | T16: 0.10077629 | V16: 0.15799814 | W16: 0.0214 | Z16: 20.792318 | AA16: 8.618701 | AB16: 0.61354935 | AD16: 7.9107966 | AE16: 26.954567 | AG16: 274.66278 | AH16: 319.8968 | AI16: 21.67 | AJ16: 12.84 | AK16: 40.438 | AM16: 0.25286326
A17: CCRD | C17: 0.2361 | D17: 0.1262796 | E17: 1.028498 | F17: 4.0326633 | H17: 0.4541 | I17: 0.12169794 | J17: 0.21816751 | M17: 8.916 | N17: 207.34883 | P17: 0.08116282 | Q17: 11.213 | S17: 26.621 | T17: 0.37532428 | V17: -0.47270757 | W17: 0.123 | Z17: 24.297565 | AA17: 22.272728 | AB17: 3.0038283 | AD17: 11.885643 | AE17: 18.84826 | AG17: 183.9 | AH17: 168.0511 | AI17: 23.6 | AJ17: 7.79 | AK17: 14.139 | AM17: 0.008844381
A18: ACFN | C18: 0.363 | D18: 0.1484058 | E18: 2.5176 | F18: 54.210526 | H18: 0.7281 | I18: 0.45967594 | J18: 0.18732932 | M18: 0.849 | N18: -141.5 | P18: 0.0050973967 | Q18: 1.012 | S18: No data | T18: 0.2195168 | V18: -0.4199 | W18: 0.5661 | Z18: 7.9996824 | AB18: 4.5831056 | AD18: 23.335278 | AE18: 56.565372 | AG18: 51.26969 | AH18: 48.024 | AI18: 20.14 | AJ18: 2.5 | AK18: 2.058 | AM18: -0.4104765
A19: TSAT | C19: -0.2579 | D19: -0.12115695 | E19: -3.055823 | F19: -4.2065806 | H19: 0.9429 | I19: 0.42947268 | J19: 0.04726162 | M19: -1009.604 | N19: 1.9206115 | P19: 2.4447832 | Q19: No data | S19: 467.09 | T19: 0.06744001 | V19: 4.2608 | W19: -0.0225 | AB19: 1.4564012 | AD19: 163.88249 | AE19: -3.46692 | AG19: 474.00955 | AH19: 2520.8516 | AI19: 33.78 | AJ19: 51.09 | AK19: 21.358 | AM19: -0.5451669
A20: CSPI | C20: -0.2162 | D20: -0.07033556 | E20: -0.009229209 | F20: -0.7283582 | H20: 0.3248 | I20: 0.42442587 | J20: -0.06792662 | M20: 1.894 | N20: 0.4735 | P20: 0.0086410055 | Q20: 3.25 | S20: No data | T20: 0.38528448 | V20: -0.5951606 | W20: -0.0013 | AA20: No data | AB20: 2.6744697 | AD20: -30.354218 | AE20: 47.11795 | AG20: 114.54882 | AH20: 89.2414 | AI20: 11.74 | AJ20: 9.86 | AK20: -2.94 | AM20: 0.26239598
A21: SPOK | C21: 0.0147 | D21: -0.014334536 | E21: 0.8055825 | F21: 0.12998775 | H21: 0.6274 | I21: 0.37097016 | J21: 0.17679387 | M21: 22.623 | N21: 0.7818829 | P21: 0.022964241 | Q21: 11.662 | S21: No data | T21: 0.10197326 | V21: -0.1437756 | W21: 0.079 | Z21: 16.435312 | AA21: 16.22549 | AB21: 1.9518101 | AD21: 10.174661 | AE21: 11.111037 | AG21: 268.31177 | AH21: 251.365 | AI21: 13.24 | AJ21: 20.6 | AK21: 24.705 | AM21: 0.3226834
A22: SILC | C22: -0.4262 | D22: -0.022336941 | E22: 0 | F22: -1.1495436 | H22: 0.2896 | I22: 0.18201664 | J22: -0.19371673 | M22: 0 | N22: 17.513794 | P22: 0.043460462 | Q22: 19.513 | S22: No data | T22: 0 | V22: 0 | W22: -0.0984 | AB22: 1.4409026 | AG22: 88.98035 | AH22: 84.483 | AI22: 14.9 | AJ22: 5.67 | AK22: 0 | AM22: -0.22127618
A23: SODI | C23: -0.1594 | D23: 0.05985148 | E23: -0.17272727 | F23: -1.0566008 | H23: 0.2126 | I23: 0.2515356 | J23: 0.03632365 | M23: 1.472 | N23: 3.0413222 | P23: 0.011678168 | Q23: No data | S23: No data | T23: 0.11592434 | V23: 0.0564 | W23: -0.0148 | AA23: No data | AB23: 3.1935618 | AD23: 89.98852 | AE23: 29.282948 | AG23: 39.761353 | AH23: 43.1045 | AI23: 21 | AJ23: 2.09 | AK23: 0.479 | AM23: -0.14264044
A24: THRY | C24: -0.1073 | D24: -0.019909434 | E24: 0.40959156 | F24: -1.0525557 | H24: 0.6736 | I24: 0.62315637 | J24: 0.1411758 | M24: 36.166 | N24: 0.49513978 | P24: 0.04012605 | Q24: No data | S24: No data | T24: 0.016459128 | V24: 1.1608 | W24: 0.0255 | Z24: 13.403597 | AA24: 10.574368 | AB24: 0.3067393 | AD24: 4.503289 | AE24: 13.711337 | AG24: 241.41597 | AH24: 495.8842 | AI24: 5.49 | AJ24: 43.58 | AK24: 110.116 | AM24: -0.18989244
A25: GAMB | C25: 0.2421 | D25: 0.38248485 | E25: 0.053852715 | F25: -0.9479942 | H25: 0.9317 | I25: 0.5895909 | J25: 0.0870249 | M25: 41.879 | N25: 26.966516 | P25: 0.0056562624 | Q25: No data | S25: No data | T25: 0.024105664 | V25: 0.6047 | W25: 0.0069 | Z25: 93.21721 | AB25: 1.1425999 | AD25: 19.141623 | AE25: 6.1462164 | AG25: 185.49243 | AH25: 257.3974 | AI25: 5.02 | AJ25: 35.17 | AK25: 13.447 | AM25: -0.056652006
A26: INLX | C26: -0.0263 | D26: 0.24878028 | E26: -0.38877454 | F26: -11.167007 | H26: 0.655 | I26: 0.67242086 | J26: -0.011173609 | M26: 1.35092 | N26: 0.6290957 | P26: 0.052598514 | Q26: No data | S26: 2.07148 | T26: 0.12072694 | V26: -0.1602 | W26: -0.0958 | AB26: 2.1353362 | AD26: -181.42876 | AE26: 25.702362 | AG26: 36.056942 | AH26: 34.721832 | AI26: 8.1638 | AJ26: 4.48 | AK26: -0.19138 | AM26: -0.3473945
A27: QXO | C27: 81.0375 | D27: 32.85121 | E27: -0.2637287 | F27: -11.401957 | H27: 0.2249 | I27: 0.1856629 | J27: 0.045423165 | M27: 78.922 | N27: 2.5809157 | P27: 0.010688081 | Q27: No data | S27: 2306.9 | T27: 0.13861166 | V27: 0.0992 | W27: -0.0162 | AA27: 82.51473 | AB27: 3.6908894 | AD27: 85.85466 | AE27: 230.41145 | AG27: 16647.37 | AH27: 18184.533 | AI27: 25.52 | AJ27: 674.39 | AK27: 211.806 | AM27: No data
A28: OOMA | C28: 0.0422 | D28: 0.09820402 | E28: 0.08137681 | F28: -1.2314509 | H28: 0.61 | I28: 0.41501996 | J28: 0.06529731 | M28: 18.885 | N28: 1.0217497 | P28: 0.021611799 | Q28: 49.658 | S28: No data | T28: 0.1422341 | V28: -0.2414 | W28: 0.015 | Z28: 147.46216 | AA28: 19.392475 | AB28: 1.2539992 | AD28: 17.94503 | AE28: 16.38761 | AG28: 317.12402 | AH28: 309.48 | AI28: 12 | AJ28: 27.6 | AK28: 17.246 | AM28: 1.3713306
A29: MGNI | C29: 0.0627 | D29: 0.30154607 | E29: 0.4035503 | F29: 2.3522234 | H29: 0.623 | I29: 0.37787536 | J29: 0.20196138 | M29: 160.728 | N29: 1.0249268 | P29: 0.08779259 | Q29: 86.335 | S29: No data | T29: 0.16507281 | V29: 0.0918 | W29: 0.0204 | Z29: 37.91349 | AA29: 17.821783 | AB29: 3.1283154 | AD29: 16.01217 | AE29: 14.135577 | AG29: 2339.3057 | AH29: 2271.983 | AI29: 15.3 | AJ29: 143.65 | AK29: 141.891 | AM29: 0.8258396
A30: NEON | C30: -0.4854 | D30: -0.15698351 | E30: 0.5353397 | F30: -1.832453 | H30: 0.9654 | I30: 2.6968594 | J30: 3.9795175 | M30: -5.89 | N30: 0.8742764 | P30: 0.040964954 | Q30: 3.595 | S30: 11.585 | T30: 0.35299674 | V30: -0.43110844 | W30: 0.4317 | Z30: 3.5117888 | AB30: 14.358853 | AD30: 2.2865608 | AE30: -3.3941257 | AG30: 31.384066 | AH30: 19.9914 | AI30: 1.88 | AJ30: 16.78 | AK30: 8.743 | AM30: 0.012710306
A31: AEYE | C31: 0.1857 | D31: 0.16468386 | E31: -0.28285024 | F31: 0.064868145 | H31: 0.7861 | I31: 0.75500757 | J31: 0.024911482 | M31: 0.829 | N31: 0.81434184 | P31: 0.049468894 | Q31: 4.854 | S31: 4.55 | T31: 0.14928801 | V31: 1.4877 | W31: -0.1104 | AB31: 3.0029135 | AD31: 129.07837 | AE31: 153.36815 | AG31: 118.03896 | AH31: 127.1422 | AI31: 9.56 | AJ31: 12.42 | AK31: 0.985 | AM31: -0.28026178
A32: AGS | C32: 0.066 | D32: 0.066023216 | E32: 1.3215129 | F32: 9.751862 | H32: 0.8747 | I32: 0.24533103 | J32: 0.418717 | M32: 24.917 | N32: 0.5554515 | P32: 0.19445185 | Q32: 59.913 | S32: No data | T32: 0.0556264 | V32: 4.2302 | W32: 0.0798 | Z32: 9.451289 | AA32: 16.172123 | AB32: 1.316834 | AD32: 6.1567907 | AE32: 40.734596 | AG32: 518.4 | AH32: 1014.9839 | AI32: 12.49 | AJ32: 41.51 | AK32: 164.856 | AM32: 0.10334572
A33: RDCM | C33: 0.1204 | D33: 0.13718125 | E33: 0.58515286 | F33: 0.9627537 | H33: 0.7332 | I33: 0.3735821 | J33: 0.14835821 | M33: -3.45 | N33: 0.8603491 | P33: 0.0014925373 | Q33: 19.574 | S33: No data | T33: 0 | V33: 0 | W33: 0.0713 | Z33: 21.908806 | AA33: 12.085218 | AB33: 3.0672328 | AD33: 20.674507 | AE33: -59.56655 | AG33: 208.06052 | AH33: 205.5046 | AI33: 12.82 | AJ33: 16.03 | AK33: 9.94 | AM33: -0.45185173
A34: BNED | C34: 0.0138 | D34: -0.04034894 | E34: -2.055683 | F34: -0.14804222 | H34: 0.2239 | I34: 0.17853361 | J34: 0.0063043754 | M34: -68.689 | N34: -3.8654473 | P34: 0.00759727 | Q34: No data | S34: No data | T34: 0.008445348 | V34: 0.466 | W34: -0.0691 | AB34: 0.19220723 | AD34: 43.844345 | AE34: -6.3089795 | AG34: 283.29736 | AH34: 433.3575 | AI34: 8.85 | AJ34: 34.05 | AK34: 9.884 | AM34: -0.099583894
A35: ASUR | C35: 0.1454 | D35: 0.14631532 | E35: -0.61552596 | F35: 0.40622172 | H35: 0.671 | I35: 0.58313006 | J35: 0.097945794 | M35: -8.562 | N35: 0.37021664 | P35: 0.22169033 | Q35: 6.579 | S35: No data | T35: 0.048134994 | V35: 0.25299478 | W35: -0.0362 | AA35: 14.319161 | AB35: 2.0858583 | AD35: 25.073792 | AE35: -37.868397 | AG35: 261.81335 | AH35: 324.2292 | AI35: 9.92 | AJ35: 27.76 | AK35: 12.931 | AM35: 0.31969485
A36: RELL | C36: 0.0617 | D36: 0.063783444 | E36: 0.012146308 | F36: -1.3055556 | H36: 0.3113 | I36: 0.2956371 | J36: 0.014628845 | M36: 8.597 | N36: 4.115366 | P36: 0.013870948 | Q36: No data | S36: No data | T36: 0.1782103 | V36: -0.22372119 | W36: 0.0009 | Z36: 883.396 | AA36: 43.406147 | AB36: 0.7411076 | AD36: 39.04324 | AE36: 13.93785 | AG36: 151.12935 | AH36: 119.8237 | AI36: 10.73 | AJ36: 14.49 | AK36: 3.069 | AM36: 0.22119126
A37: EXPI | C37: -0.1637 | D37: 0.20546083 | E37: -0.1216822 | F37: -0.42658794 | H37: 0.0692 | I37: 0.075601004 | J37: -0.0012465938 | M37: 108.388 | N37: 0.533395 | P37: 0.0028006737 | Q37: 66.979 | S37: No data | T37: 0.2458043 | V37: -0.4793 | W37: -0.0438 | AB37: 0.3903017 | AD37: -288.8033 | AE37: 12.368758 | AG37: 1531.1859 | AH37: 1340.625 | AI37: 9.15 | AJ37: 158.84 | AK37: -4.642 | AM37: 0.6583921
A38: ACCS | C38: -0.3445 | D38: 0.029354563 | E38: -1.4855297 | F38: 8.827351 | H38: 0.7708 | I38: 0.8104076 | J38: -0.76118946 | M38: 3.011 | N38: 2.7077339 | P38: 0.012048192 | Q38: No data | S38: No data | T38: 0.09024653 | V38: -0.036789626 | W38: -0.1121 | AA38: 18.600954 | AB38: 2.0892644 | AD38: -2.668694 | AE38: 13.159117 | AG38: 37.52722 | AH38: 39.6221 | AI38: 10.53 | AJ38: 3.87 | AK38: -14.847 | AM38: No data
A39: MITK | C39: 0.0442 | D39: 0.1214368 | E39: 0.19268346 | F39: 1.6833435 | H39: 0.8509 | I39: 0.46717978 | J39: 0.28375936 | M39: 54.185 | N39: 1.7912396 | P39: 0.006427701 | Q39: 35.284 | S39: No data | T39: 0.33576557 | V39: 0.00983526 | W39: 0.0204 | Z39: 53.196056 | AA39: 9.1855755 | AB39: 2.603984 | AD39: 9.223078 | AE39: 8.679071 | AG39: 487.61346 | AH39: 470.2755 | AI39: 10.25 | AJ39: 45.65 | AK39: 50.989 | AM39: 0.16470626
A40: CTLP | C40: 0.1294 | D40: 0.1481149 | E40: 0.8146811 | F40: 3.4285293 | H40: 0.4111 | I40: 0.21004911 | J40: -0.021895595 | M40: 22.685 | N40: -3.3463638 | P40: 0.053256124 | Q40: 17.963 | S40: No data | T40: 0.1411631 | V40: -0.0656 | W40: 0.1662 | Z40: 13.318094 | AA40: 23.725182 | AB40: 2.558332 | AD40: -157.21867 | AE40: 34.51395 | AG40: 788.92883 | AH40: 782.949 | AI40: 10.85 | AJ40: 73.7 | AK40: -4.98 | AM40: 0.15815394
...

Sheet US - Utilities
A1: Ticker | B1: Company Name | C1: Popular | D1: MCC Link | E1: MCC Link | F1: MKT CAP | G1: REV | H1: REV YoY | I1: REV 5YR CAGR | J1: EBITDA | K1: EBITDA YoY | L1: EBITDA 5Y CAGR | M1: EV/EBITDA | N1: EPS | O1: EPS YoY | P1: NI 5YR CAGR | Q1: ROA | R1: ROE | S1: P/B | T1: P/E | U1: FORWARD P/E | V1: DIVIDEND % | W1: EV | X1: STOCK PRICE | Y1: SHARES OUT
A2: WAVE | B2: Eco Wave Power | C2: Lowest | D2: [READ PITCH](https://community.microcapclub.com/forums/topic/3423-eco-wave-power-wave/#comment-76327) | E2: =IFERROR(__xludf.DUMMYFUNCTION("IFERROR(HYPERLINK(REGEXEXTRACT(D2,""\(([^)]*)\)""),REGEXEXTRACT(D2,""\[([^\]]+)\]"")),"""") "),"READ PITCH") -> READ PITCH | F2: =VLOOKUP($A2, RawData!$A:$AJ, 33, FALSE) -> 34.82723 | G2: =VLOOKUP($A2, RawData!$A:$AJ, 2, FALSE) | H2: =VLOOKUP($A2, RawData!$A:$AJ, 3, FALSE) -> 0.2645 | I2: =VLOOKUP($A2, RawData!$A:$AJ, 4, FALSE) -> No data | J2: =VLOOKUP($A2, RawData!$A:$AM, 37, FALSE) -> -2.143 | K2: =VLOOKUP($A2, RawData!$A:$AM, 38, FALSE) | L2: =VLOOKUP($A2, RawData!$A:$AM, 39, FALSE) -> No data | M2: =VLOOKUP($A2, RawData!$A:$AJ, 30, FALSE) -> -13.758749 | N2: =VLOOKUP($A2, RawData!$A:$AJ, 5, FALSE) -> -0.3556507 | O2: =VLOOKUP($A2, RawData!$A:$AJ, 6, FALSE) -> No data | P2: =VLOOKUP($A2, RawData!$A:$AJ, 7, FALSE) | Q2: =VLOOKUP($A2, RawData!$A:$AJ, 23, FALSE) -> -0.2247 | R2: =VLOOKUP($A2, RawData!$A:$AJ, 24, FALSE) | S2: =VLOOKUP($A2, RawData!$A:$AJ, 29, FALSE) | T2: =VLOOKUP($A2, RawData!$A:$AJ, 26, FALSE) | U2: =VLOOKUP($A2, RawData!$A:$AJ, 27, FALSE) | V2: =VLOOKUP($A2, RawData!$A:$AJ,32, FALSE) | W2: =VLOOKUP($A2, RawData!$A:$AJ, 33, FALSE) -> 34.82723 | X2: =VLOOKUP($A2, RawData!$A:$AJ, 35, FALSE) -> 5.9 | Y2: =VLOOKUP($A2, RawData!$A:$AJ, 36, FALSE) -> 5.84
A3: EUSP | B3: EuroSite Power Inc. | C3: Lowest | D3: [READ PITCH](https://community.microcapclub.com/forums/topic/4564-eurosite-power-inc-eusp/#comment-92070) | E3: =IFERROR(__xludf.DUMMYFUNCTION("IFERROR(HYPERLINK(REGEXEXTRACT(D3,""\(([^)]*)\)""),REGEXEXTRACT(D3,""\[([^\]]+)\]"")),"""") "),"READ PITCH") -> READ PITCH | F3: =VLOOKUP($A3, RawData!$A:$AJ, 33, FALSE) -> 4.19544 | G3: =VLOOKUP($A3, RawData!$A:$AJ, 2, FALSE) -> No data | H3: =VLOOKUP($A3, RawData!$A:$AJ, 3, FALSE) -> -0.56 | I3: =VLOOKUP($A3, RawData!$A:$AJ, 4, FALSE) -> 0.045778085 | J3: =VLOOKUP($A3, RawData!$A:$AM, 37, FALSE) -> -7.18099 | K3: =VLOOKUP($A3, RawData!$A:$AM, 38, FALSE) -> No data | L3: =VLOOKUP($A3, RawData!$A:$AM, 39, FALSE) -> 0.32108018 | M3: =VLOOKUP($A3, RawData!$A:$AJ, 30, FALSE) -> 0.30796728 | N3: =VLOOKUP($A3, RawData!$A:$AJ, 5, FALSE) -> -0.091298684 | O3: =VLOOKUP($A3, RawData!$A:$AJ, 6, FALSE) -> -20.9459 | P3: =VLOOKUP($A3, RawData!$A:$AJ, 7, FALSE) -> No data | Q3: =VLOOKUP($A3, RawData!$A:$AJ, 23, FALSE) -> -0.8302 | R3: =VLOOKUP($A3, RawData!$A:$AJ, 24, FALSE) -> No data | S3: =VLOOKUP($A3, RawData!$A:$AJ, 29, FALSE) -> No data | T3: =VLOOKUP($A3, RawData!$A:$AJ, 26, FALSE) | U3: =VLOOKUP($A3, RawData!$A:$AJ, 27, FALSE) -> No data | V3: =VLOOKUP($A3, RawData!$A:$AJ,32, FALSE) -> No data | W3: =VLOOKUP($A3, RawData!$A:$AJ, 33, FALSE) -> 4.19544 | X3: =VLOOKUP($A3, RawData!$A:$AJ, 35, FALSE) -> 0.051 | Y3: =VLOOKUP($A3, RawData!$A:$AJ, 36, FALSE) -> 82.26
A4: ENG | B4: ENGlobal | C4: Lowest | D4: [READ PITCH](https://community.microcapclub.com/forums/topic/3501-englobal-eng/#comment-77741) | E4: =IFERROR(__xludf.DUMMYFUNCTION("IFERROR(HYPERLINK(REGEXEXTRACT(D4,""\(([^)]*)\)""),REGEXEXTRACT(D4,""\[([^\]]+)\]"")),"""") "),"READ PITCH") -> READ PITCH | F4: =VLOOKUP($A4, RawData!$A:$AJ, 33, FALSE) -> 2.32 | G4: =VLOOKUP($A4, RawData!$A:$AJ, 2, FALSE) | H4: =VLOOKUP($A4, RawData!$A:$AJ, 3, FALSE) -> -0.3871 | I4: =VLOOKUP($A4, RawData!$A:$AJ, 4, FALSE) -> -0.13786851 | J4: =VLOOKUP($A4, RawData!$A:$AM, 37, FALSE) -> -5.585 | K4: =VLOOKUP($A4, RawData!$A:$AM, 38, FALSE) | L4: =VLOOKUP($A4, RawData!$A:$AM, 39, FALSE) -> 0.019537123 | M4: =VLOOKUP($A4, RawData!$A:$AJ, 30, FALSE) -> -0.67358994 | N4: =VLOOKUP($A4, RawData!$A:$AJ, 5, FALSE) -> -1.3306202 | O4: =VLOOKUP($A4, RawData!$A:$AJ, 6, FALSE) -> -0.6921076 | P4: =VLOOKUP($A4, RawData!$A:$AJ, 7, FALSE) | Q4: =VLOOKUP($A4, RawData!$A:$AJ, 23, FALSE) -> -0.4368 | R4: =VLOOKUP($A4, RawData!$A:$AJ, 24, FALSE) | S4: =VLOOKUP($A4, RawData!$A:$AJ, 29, FALSE) | T4: =VLOOKUP($A4, RawData!$A:$AJ, 26, FALSE) | U4: =VLOOKUP($A4, RawData!$A:$AJ, 27, FALSE) -> 1.0699426 | V4: =VLOOKUP($A4, RawData!$A:$AJ,32, FALSE) | W4: =VLOOKUP($A4, RawData!$A:$AJ, 33, FALSE) -> 2.32 | X4: =VLOOKUP($A4, RawData!$A:$AJ, 35, FALSE) -> No data | Y4: =VLOOKUP($A4, RawData!$A:$AJ, 36, FALSE) -> 5.16
A5: GNE | B5: Genie Energy | C5: Low | D5: [READ PITCH](https://community.microcapclub.com/forums/topic/3199-genie-energy-ltd-gne/#comment-72283) | E5: =IFERROR(__xludf.DUMMYFUNCTION("IFERROR(HYPERLINK(REGEXEXTRACT(D5,""\(([^)]*)\)""),REGEXEXTRACT(D5,""\[([^\]]+)\]"")),"""") "),"READ PITCH") -> READ PITCH | F5: =VLOOKUP($A5, RawData!$A:$AJ, 33, FALSE) -> 377.5485 | G5: =VLOOKUP($A5, RawData!$A:$AJ, 2, FALSE) | H5: =VLOOKUP($A5, RawData!$A:$AJ, 3, FALSE) -> 0.1312 | I5: =VLOOKUP($A5, RawData!$A:$AJ, 4, FALSE) -> 0.06155537 | J5: =VLOOKUP($A5, RawData!$A:$AM, 37, FALSE) -> 1.878 | K5: =VLOOKUP($A5, RawData!$A:$AM, 38, FALSE) | L5: =VLOOKUP($A5, RawData!$A:$AM, 39, FALSE) -> -0.4143127 | M5: =VLOOKUP($A5, RawData!$A:$AJ, 30, FALSE) -> 150.76901 | N5: =VLOOKUP($A5, RawData!$A:$AJ, 5, FALSE) -> 0.18308796 | O5: =VLOOKUP($A5, RawData!$A:$AJ, 6, FALSE) -> 0.41564506 | P5: =VLOOKUP($A5, RawData!$A:$AJ, 7, FALSE) | Q5: =VLOOKUP($A5, RawData!$A:$AJ, 23, FALSE) -> 0.0127 | R5: =VLOOKUP($A5, RawData!$A:$AJ, 24, FALSE) | S5: =VLOOKUP($A5, RawData!$A:$AJ, 29, FALSE) | T5: =VLOOKUP($A5, RawData!$A:$AJ, 26, FALSE) -> 79.08767 | U5: =VLOOKUP($A5, RawData!$A:$AJ, 27, FALSE) -> 24.905401 | V5: =VLOOKUP($A5, RawData!$A:$AJ,32, FALSE) | W5: =VLOOKUP($A5, RawData!$A:$AJ, 33, FALSE) -> 377.5485 | X5: =VLOOKUP($A5, RawData!$A:$AJ, 35, FALSE) -> 14.48 | Y5: =VLOOKUP($A5, RawData!$A:$AJ, 36, FALSE) -> 26.49

Sheet US - Technology
A1: Ticker | B1: Company Name | C1: Popular | D1: MCC Link | E1: MCC Link | F1: MKT CAP | G1: REV | H1: REV YoY | I1: REV 5YR CAGR | J1: EBITDA | K1: EBITDA YoY | L1: EBITDA 5Y CAGR | M1: EV/EBITDA | N1: EPS | O1: EPS YoY | P1: NI 5YR CAGR | Q1: GM | R1: OPmargin | S1: FCF | T1: FCF YoY | U1: ROA | V1: ROE | W1: CROCI | X1: PE | Y1: FORWARD PE | Z1: P/S | AA1: EV/FCF | AB1: DIVIDEND % | AC1: EV | AD1: STOCK PRICE | AE1: SHARES OUT
A2: GAME | B2: Gamesquare Holdings | C2: Low | D2: [READ PITCH](https://community.microcapclub.com/forums/topic/1573-gamesquare-holdings-inc-game/#comment-35335) | E2: =IFERROR(__xludf.DUMMYFUNCTION("IFERROR(HYPERLINK(REGEXEXTRACT(D2,""\(([^)]*)\)""),REGEXEXTRACT(D2,""\[([^\]]+)\]"")),"""") "),"READ PITCH") -> READ PITCH | F2: =VLOOKUP($A2, RawData!$A:$AJ, 33, FALSE) -> 46.263557 | G2: =VLOOKUP($A2, RawData!$A:$AJ, 2, FALSE) | H2: =VLOOKUP($A2, RawData!$A:$AJ, 3, FALSE) -> -0.4248 | I2: =VLOOKUP($A2, RawData!$A:$AJ, 4, FALSE) -> -0.12822299 | J2: =VLOOKUP($A2, RawData!$A:$AM, 37, FALSE) -> -35.05172 | K2: =VLOOKUP($A2, RawData!$A:$AM, 38, FALSE) | L2: =VLOOKUP($A2, RawData!$A:$AM, 39, FALSE) -> -0.15716498 | M2: =VLOOKUP($A2, RawData!$A:$AJ, 30, FALSE) -> -1.1254569 | N2: =VLOOKUP($A2, RawData!$A:$AJ, 5, FALSE) -> -0.31139722 | O2: =VLOOKUP($A2, RawData!$A:$AJ, 6, FALSE) -> -0.46814975 | P2: =VLOOKUP($A2, RawData!$A:$AJ, 7, FALSE) | Q2: =VLOOKUP($A2, RawData!$A:$AJ, 8, FALSE) -> 0.1917 | R2: =VLOOKUP($A2, RawData!$A:$AJ, 11, FALSE) | S2: =VLOOKUP($A2, RawData!$A:$AJ, 13, FALSE) -> -22.84184 | T2: =VLOOKUP($A2, RawData!$A:$AJ, 14, FALSE) -> 0.720281 | U2: =VLOOKUP($A2, RawData!$A:$AJ, 23, FALSE) -> -0.3931 | V2: =VLOOKUP($A2, RawData!$A:$AJ, 24, FALSE) | W2: =VLOOKUP($A2, RawData!$A:$AJ, 25, FALSE) | X2: =VLOOKUP($A2, RawData!$A:$AJ, 26, FALSE) | Y2: =VLOOKUP($A2, RawData!$A:$AJ, 27, FALSE) | Z2: =VLOOKUP($A2, RawData!$A:$AJ, 28, FALSE) -> 0.633634 | AA2: =VLOOKUP($A2, RawData!$A:$AJ, 31, FALSE) -> -1.7270608 | AB2: =VLOOKUP($A2, RawData!$A:$AJ,32, FALSE) | AC2: =VLOOKUP($A2, RawData!$A:$AJ, 34, FALSE) -> 39.449177 | AD2: =VLOOKUP($A2, RawData!$A:$AJ, 35, FALSE) -> 0.4621 | AE2: =VLOOKUP($A2, RawData!$A:$AJ, 36, FALSE) -> 98.38
A3: PI | B3: Impinj | C3: Low | D3: [READ PITCH](https://community.microcapclub.com/forums/topic/2036-impinj-pi/#comment-46319) | E3: =IFERROR(__xludf.DUMMYFUNCTION("IFERROR(HYPERLINK(REGEXEXTRACT(D3,""\(([^)]*)\)""),REGEXEXTRACT(D3,""\[([^\]]+)\]"")),"""") "),"READ PITCH") -> READ PITCH | F3: =VLOOKUP($A3, RawData!$A:$AJ, 33, FALSE) -> 6404.815 | G3: =VLOOKUP($A3, RawData!$A:$AJ, 2, FALSE) | H3: =VLOOKUP($A3, RawData!$A:$AJ, 3, FALSE) -> 0.0424 | I3: =VLOOKUP($A3, RawData!$A:$AJ, 4, FALSE) -> 0.20215866 | J3: =VLOOKUP($A3, RawData!$A:$AM, 37, FALSE) -> 7.213 | K3: =VLOOKUP($A3, RawData!$A:$AM, 38, FALSE) | L3: =VLOOKUP($A3, RawData!$A:$AM, 39, FALSE) -> -0.030969055 | M3: =VLOOKUP($A3, RawData!$A:$AJ, 30, FALSE) -> 788.76843 | N3: =VLOOKUP($A3, RawData!$A:$AJ, 5, FALSE) -> -0.4117569 | O3: =VLOOKUP($A3, RawData!$A:$AJ, 6, FALSE) -> -1.2009693 | P3: =VLOOKUP($A3, RawData!$A:$AJ, 7, FALSE) | Q3: =VLOOKUP($A3, RawData!$A:$AJ, 8, FALSE) -> 0.5221 | R3: =VLOOKUP($A3, RawData!$A:$AJ, 11, FALSE) | S3: =VLOOKUP($A3, RawData!$A:$AJ, 13, FALSE) -> 40.267 | T3: =VLOOKUP($A3, RawData!$A:$AJ, 14, FALSE) -> 0.3955268 | U3: =VLOOKUP($A3, RawData!$A:$AJ, 23, FALSE) -> -0.0249 | V3: =VLOOKUP($A3, RawData!$A:$AJ, 24, FALSE) | W3: =VLOOKUP($A3, RawData!$A:$AJ, 25, FALSE) | X3: =VLOOKUP($A3, RawData!$A:$AJ, 26, FALSE) | Y3: =VLOOKUP($A3, RawData!$A:$AJ, 27, FALSE) -> 86.15877 | Z3: =VLOOKUP($A3, RawData!$A:$AJ, 28, FALSE) -> 15.177392 | AA3: =VLOOKUP($A3, RawData!$A:$AJ, 31, FALSE) -> 141.29155 | AB3: =VLOOKUP($A3, RawData!$A:$AJ,32, FALSE) | AC3: =VLOOKUP($A3, RawData!$A:$AJ, 34, FALSE) -> 5689.3867 | AD3: =VLOOKUP($A3, RawData!$A:$AJ, 35, FALSE) -> 181.36 | AE3: =VLOOKUP($A3, RawData!$A:$AJ, 36, FALSE) -> 30.11
A4: IDT | B4: IDT Corporation | C4: Lowest | D4: [READ PITCH](https://community.microcapclub.com/forums/topic/2350-idt-corporation-idt/#comment-54574) | E4: =IFERROR(__xludf.DUMMYFUNCTION("IFERROR(HYPERLINK(REGEXEXTRACT(D4,""\(([^)]*)\)""),REGEXEXTRACT(D4,""\[([^\]]+)\]"")),"""") "),"READ PITCH") -> READ PITCH | F4: =VLOOKUP($A4, RawData!$A:$AJ, 33, FALSE) -> 1272.4558 | G4: =VLOOKUP($A4, RawData!$A:$AJ, 2, FALSE) | H4: =VLOOKUP($A4, RawData!$A:$AJ, 3, FALSE) -> 0.0252 | I4: =VLOOKUP($A4, RawData!$A:$AJ, 4, FALSE) -> -0.015953567 | J4: =VLOOKUP($A4, RawData!$A:$AM, 37, FALSE) -> 128.926 | K4: =VLOOKUP($A4, RawData!$A:$AM, 38, FALSE) | L4: =VLOOKUP($A4, RawData!$A:$AM, 39, FALSE) -> 0.19638498 | M4: =VLOOKUP($A4, RawData!$A:$AJ, 30, FALSE) -> 8.653185 | N4: =VLOOKUP($A4, RawData!$A:$AJ, 5, FALSE) -> 3.2392502 | O4: =VLOOKUP($A4, RawData!$A:$AJ, 6, FALSE) -> 0.096753284 | P4: =VLOOKUP($A4, RawData!$A:$AJ, 7, FALSE) | Q4: =VLOOKUP($A4, RawData!$A:$AJ, 8, FALSE) -> 0.367 | R4: =VLOOKUP($A4, RawData!$A:$AJ, 11, FALSE) | S4: =VLOOKUP($A4, RawData!$A:$AJ, 13, FALSE) -> 92.905 | T4: =VLOOKUP($A4, RawData!$A:$AJ, 14, FALSE) -> 2.1266053 | U4: =VLOOKUP($A4, RawData!$A:$AJ, 23, FALSE) -> 0.1322 | V4: =VLOOKUP($A4, RawData!$A:$AJ, 24, FALSE) | W4: =VLOOKUP($A4, RawData!$A:$AJ, 25, FALSE) | X4: =VLOOKUP($A4, RawData!$A:$AJ, 26, FALSE) -> 16.068533 | Y4: =VLOOKUP($A4, RawData!$A:$AJ, 27, FALSE) -> 15.501221 | Z4: =VLOOKUP($A4, RawData!$A:$AJ, 28, FALSE) -> 1.0483767 | AA4: =VLOOKUP($A4, RawData!$A:$AJ, 31, FALSE) -> 12.008185 | AB4: =VLOOKUP($A4, RawData!$A:$AJ,32, FALSE) | AC4: =VLOOKUP($A4, RawData!$A:$AJ, 34, FALSE) -> 1115.6205 | AD4: =VLOOKUP($A4, RawData!$A:$AJ, 35, FALSE) -> 52.05 | AE4: =VLOOKUP($A4, RawData!$A:$AJ, 36, FALSE) -> 25.07
A5: BKTI | B5: BK Technologies | C5: Medium | D5: [READ PITCH](https://community.microcapclub.com/forums/topic/3773-bk-technologies-bkti/#comment-81787) | E5: =IFERROR(__xludf.DUMMYFUNCTION("IFERROR(HYPERLINK(REGEXEXTRACT(D5,""\(([^)]*)\)""),REGEXEXTRACT(D5,""\[([^\]]+)\]"")),"""") "),"READ PITCH") -> READ PITCH | F5: =VLOOKUP($A5, RawData!$A:$AJ, 33, FALSE) -> 288.68884 | G5: =VLOOKUP($A5, RawData!$A:$AJ, 2, FALSE) | H5: =VLOOKUP($A5, RawData!$A:$AJ, 3, FALSE) -> 0.0463 | I5: =VLOOKUP($A5, RawData!$A:$AJ, 4, FALSE) -> 0.1438503 | J5: =VLOOKUP($A5, RawData!$A:$AM, 37, FALSE) -> 13.289 | K5: =VLOOKUP($A5, RawData!$A:$AM, 38, FALSE) | L5: =VLOOKUP($A5, RawData!$A:$AM, 39, FALSE) -> 0.74884135 | M5: =VLOOKUP($A5, RawData!$A:$AJ, 30, FALSE) -> 23.659426 | N5: =VLOOKUP($A5, RawData!$A:$AJ, 5, FALSE) -> 3.1868632 | O5: =VLOOKUP($A5, RawData!$A:$AJ, 6, FALSE) -> 3.362202 | P5: =VLOOKUP($A5, RawData!$A:$AJ, 7, FALSE) | Q5: =VLOOKUP($A5, RawData!$A:$AJ, 8, FALSE) -> 0.4366 | R5: =VLOOKUP($A5, RawData!$A:$AJ, 11, FALSE) | S5: =VLOOKUP($A5, RawData!$A:$AJ, 13, FALSE) -> 12.283 | T5: =VLOOKUP($A5, RawData!$A:$AJ, 14, FALSE) -> 8.8942795 | U5: =VLOOKUP($A5, RawData!$A:$AJ, 23, FALSE) -> 0.2218 | V5: =VLOOKUP($A5, RawData!$A:$AJ, 24, FALSE) | W5: =VLOOKUP($A5, RawData!$A:$AJ, 25, FALSE) | X5: =VLOOKUP($A5, RawData!$A:$AJ, 26, FALSE) -> 27.447052 | Y5: =VLOOKUP($A5, RawData!$A:$AJ, 27, FALSE) -> 21.765203 | Z5: =VLOOKUP($A5, RawData!$A:$AJ, 28, FALSE) -> 4.1654506 | AA5: =VLOOKUP($A5, RawData!$A:$AJ, 31, FALSE) -> 25.597176 | AB5: =VLOOKUP($A5, RawData!$A:$AJ,32, FALSE) | AC5: =VLOOKUP($A5, RawData!$A:$AJ, 34, FALSE) -> 314.4101 | AD5: =VLOOKUP($A5, RawData!$A:$AJ, 35, FALSE) -> 87.47 | AE5: =VLOOKUP($A5, RawData!$A:$AJ, 36, FALSE) -> 3.73
A6: RDVT | B6: Red Violet | C6: Medium | D6: [READ PITCH](https://community.microcapclub.com/forums/topic/2089-red-violet-rdvt/#comment-47842) | E6: =IFERROR(__xludf.DUMMYFUNCTION("IFERROR(HYPERLINK(REGEXEXTRACT(D6,""\(([^)]*)\)""),REGEXEXTRACT(D6,""\[([^\]]+)\]"")),"""") "),"READ PITCH") -> READ PITCH | F6: =VLOOKUP($A6, RawData!$A:$AJ, 33, FALSE) -> 745.3378 | G6: =VLOOKUP($A6, RawData!$A:$AJ, 2, FALSE) | H6: =VLOOKUP($A6, RawData!$A:$AJ, 3, FALSE) -> 0.2227 | I6: =VLOOKUP($A6, RawData!$A:$AJ, 4, FALSE) -> 0.2003615 | J6: =VLOOKUP($A6, RawData!$A:$AM, 37, FALSE) -> 22.293 | K6: =VLOOKUP($A6, RawData!$A:$AM, 38, FALSE) | L6: =VLOOKUP($A6, RawData!$A:$AM, 39, FALSE) -> No data | M6: =VLOOKUP($A6, RawData!$A:$AJ, 30, FALSE) -> 30.11736 | N6: =VLOOKUP($A6, RawData!$A:$AJ, 5, FALSE) -> 0.79503196 | O6: =VLOOKUP($A6, RawData!$A:$AJ, 6, FALSE) -> 1.2094674 | P6: =VLOOKUP($A6, RawData!$A:$AJ, 7, FALSE) | Q6: =VLOOKUP($A6, RawData!$A:$AJ, 8, FALSE) -> 0.835 | R6: =VLOOKUP($A6, RawData!$A:$AJ, 11, FALSE) | S6: =VLOOKUP($A6, RawData!$A:$AJ, 13, FALSE) -> 18.936 | T6: =VLOOKUP($A6, RawData!$A:$AJ, 14, FALSE) -> 1.5683286 | U6: =VLOOKUP($A6, RawData!$A:$AJ, 23, FALSE) -> 0.1081 | V6: =VLOOKUP($A6, RawData!$A:$AJ, 24, FALSE) | W6: =VLOOKUP($A6, RawData!$A:$AJ, 25, FALSE) | X6: =VLOOKUP($A6, RawData!$A:$AJ, 26, FALSE) -> 63.98485 | Y6: =VLOOKUP($A6, RawData!$A:$AJ, 27, FALSE) -> 43.60722 | Z6: =VLOOKUP($A6, RawData!$A:$AJ, 28, FALSE) -> 8.293414 | AA6: =VLOOKUP($A6, RawData!$A:$AJ, 31, FALSE) -> 35.456608 | AB6: =VLOOKUP($A6, RawData!$A:$AJ,32, FALSE) | AC6: =VLOOKUP($A6, RawData!$A:$AJ, 34, FALSE) -> 671.4063 | AD6: =VLOOKUP($A6, RawData!$A:$AJ, 35, FALSE) -> 50.87 | AE6: =VLOOKUP($A6, RawData!$A:$AJ, 36, FALSE) -> 14.09
A7: INOD | B7: Innodata | C7: Low | D7: [READ PITCH](https://community.microcapclub.com/forums/topic/1236-innodata-inod/#comment-28632) | E7: =IFERROR(__xludf.DUMMYFUNCTION("IFERROR(HYPERLINK(REGEXEXTRACT(D7,""\(([^)]*)\)""),REGEXEXTRACT(D7,""\[([^\]]+)\]"")),"""") "),"READ PITCH") -> READ PITCH | F7: =VLOOKUP($A7, RawData!$A:$AJ, 33, FALSE) -> 2107.9204 | G7: =VLOOKUP($A7, RawData!$A:$AJ, 2, FALSE) | H7: =VLOOKUP($A7, RawData!$A:$AJ, 3, FALSE) -> 0.7357 | I7: =VLOOKUP($A7, RawData!$A:$AJ, 4, FALSE) -> 0.3285289 | J7: =VLOOKUP($A7, RawData!$A:$AM, 37, FALSE) -> 46.686 | K7: =VLOOKUP($A7, RawData!$A:$AM, 38, FALSE) | L7: =VLOOKUP($A7, RawData!$A:$AM, 39, FALSE) -> 0.7872666 | M7: =VLOOKUP($A7, RawData!$A:$AJ, 30, FALSE) -> 41.706306 | N7: =VLOOKUP($A7, RawData!$A:$AJ, 5, FALSE) -> 1.055995 | O7: =VLOOKUP($A7, RawData!$A:$AJ, 6, FALSE) -> 0.68085533 | P7: =VLOOKUP($A7, RawData!$A:$AJ, 7, FALSE) | Q7: =VLOOKUP($A7, RawData!$A:$AJ, 8, FALSE) -> 0.4132 | R7: =VLOOKUP($A7, RawData!$A:$AJ, 11, FALSE) | S7: =VLOOKUP($A7, RawData!$A:$AJ, 13, FALSE) -> 40.697 | T7: =VLOOKUP($A7, RawData!$A:$AJ, 14, FALSE) -> 3.68933 | U7: =VLOOKUP($A7, RawData!$A:$AJ, 23, FALSE) -> 0.2567 | V7: =VLOOKUP($A7, RawData!$A:$AJ, 24, FALSE) | W7: =VLOOKUP($A7, RawData!$A:$AJ, 25, FALSE) | X7: =VLOOKUP($A7, RawData!$A:$AJ, 26, FALSE) -> 59.81089 | Y7: =VLOOKUP($A7, RawData!$A:$AJ, 27, FALSE) -> 70.241 | Z7: =VLOOKUP($A7, RawData!$A:$AJ, 28, FALSE) -> 8.43839 | AA7: =VLOOKUP($A7, RawData!$A:$AJ, 31, FALSE) -> 47.843838 | AB7: =VLOOKUP($A7, RawData!$A:$AJ,32, FALSE) | AC7: =VLOOKUP($A7, RawData!$A:$AJ, 34, FALSE) -> 1947.1006 | AD7: =VLOOKUP($A7, RawData!$A:$AJ, 35, FALSE) -> 63.16 | AE7: =VLOOKUP($A7, RawData!$A:$AJ, 36, FALSE) -> 31.86
A8: EACO | B8: EACO Corporation | C8: Low | D8: [READ PITCH](https://community.microcapclub.com/forums/topic/1049-eaco-corporation-eaco/#comment-22708) | E8: =IFERROR(__xludf.DUMMYFUNCTION("IFERROR(HYPERLINK(REGEXEXTRACT(D8,""\(([^)]*)\)""),REGEXEXTRACT(D8,""\[([^\]]+)\]"")),"""") "),"READ PITCH") -> READ PITCH | F8: =VLOOKUP($A8, RawData!$A:$AJ, 33, FALSE) -> 413.23517 | G8: =VLOOKUP($A8, RawData!$A:$AJ, 2, FALSE) | H8: =VLOOKUP($A8, RawData!$A:$AJ, 3, FALSE) -> 0.1631 | I8: =VLOOKUP($A8, RawData!$A:$AJ, 4, FALSE) -> 0.12024409 | J8: =VLOOKUP($A8, RawData!$A:$AM, 37, FALSE) -> 41.932 | K8: =VLOOKUP($A8, RawData!$A:$AM, 38, FALSE) | L8: =VLOOKUP($A8, RawData!$A:$AM, 39, FALSE) -> 0.25658518 | M8: =VLOOKUP($A8, RawData!$A:$AJ, 30, FALSE) -> 9.878493 | N8: =VLOOKUP($A8, RawData!$A:$AJ, 5, FALSE) -> 6.1020575 | O8: =VLOOKUP($A8, RawData!$A:$AJ, 6, FALSE) -> 1.0429871 | P8: =VLOOKUP($A8, RawData!$A:$AJ, 7, FALSE) | Q8: =VLOOKUP($A8, RawData!$A:$AJ, 8, FALSE) -> 0.3011 | R8: =VLOOKUP($A8, RawData!$A:$AJ, 11, FALSE) | S8: =VLOOKUP($A8, RawData!$A:$AJ, 13, FALSE) -> 18.429 | T8: =VLOOKUP($A8, RawData!$A:$AJ, 14, FALSE) -> -0.7756313 | U8: =VLOOKUP($A8, RawData!$A:$AJ, 23, FALSE) -> 0.1472 | V8: =VLOOKUP($A8, RawData!$A:$AJ, 24, FALSE) | W8: =VLOOKUP($A8, RawData!$A:$AJ, 25, FALSE) | X8: =VLOOKUP($A8, RawData!$A:$AJ, 26, FALSE) -> 13.929728 | Y8: =VLOOKUP($A8, RawData!$A:$AJ, 27, FALSE) | Z8: =VLOOKUP($A8, RawData!$A:$AJ, 28, FALSE) -> 1.027658 | AA8: =VLOOKUP($A8, RawData!$A:$AJ, 31, FALSE) -> 22.476803 | AB8: =VLOOKUP($A8, RawData!$A:$AJ,32, FALSE) | AC8: =VLOOKUP($A8, RawData!$A:$AJ, 34, FALSE) -> 414.225 | AD8: =VLOOKUP($A8, RawData!$A:$AJ, 35, FALSE) -> 85 | AE8: =VLOOKUP($A8, RawData!$A:$AJ, 36, FALSE) -> 4.86
A9: IIIV | B9: i3 Verticals | C9: Low | D9: [READ PITCH](https://community.microcapclub.com/forums/topic/4122-i3-verticals-inc-iiiv/#comment-85768) | E9: =IFERROR(__xludf.DUMMYFUNCTION("IFERROR(HYPERLINK(REGEXEXTRACT(D9,""\(([^)]*)\)""),REGEXEXTRACT(D9,""\[([^\]]+)\]"")),"""") "),"READ PITCH") -> READ PITCH | F9: =VLOOKUP($A9, RawData!$A:$AJ, 33, FALSE) -> 884.8759 | G9: =VLOOKUP($A9, RawData!$A:$AJ, 2, FALSE) | H9: =VLOOKUP($A9, RawData!$A:$AJ, 3, FALSE) -> -0.2369 | I9: =VLOOKUP($A9, RawData!$A:$AJ, 4, FALSE) -> 0.0904248 | J9: =VLOOKUP($A9, RawData!$A:$AM, 37, FALSE) -> 40.91 | K9: =VLOOKUP($A9, RawData!$A:$AM, 38, FALSE) | L9: =VLOOKUP($A9, RawData!$A:$AM, 39, FALSE) -> 0.11801729 | M9: =VLOOKUP($A9, RawData!$A:$AJ, 30, FALSE) -> 19.736616 | N9: =VLOOKUP($A9, RawData!$A:$AJ, 5, FALSE) -> 0.5524884 | O9: =VLOOKUP($A9, RawData!$A:$AJ, 6, FALSE) -> -0.8439366 | P9: =VLOOKUP($A9, RawData!$A:$AJ, 7, FALSE) | Q9: =VLOOKUP($A9, RawData!$A:$AJ, 8, FALSE) -> 0.6647 | R9: =VLOOKUP($A9, RawData!$A:$AJ, 11, FALSE) | S9: =VLOOKUP($A9, RawData!$A:$AJ, 13, FALSE) -> -4.441 | T9: =VLOOKUP($A9, RawData!$A:$AJ, 14, FALSE) -> -0.13457575 | U9: =VLOOKUP($A9, RawData!$A:$AJ, 23, FALSE) -> 0.0271 | V9: =VLOOKUP($A9, RawData!$A:$AJ, 24, FALSE) | W9: =VLOOKUP($A9, RawData!$A:$AJ, 25, FALSE) | X9: =VLOOKUP($A9, RawData!$A:$AJ, 26, FALSE) -> 48.906002 | Y9: =VLOOKUP($A9, RawData!$A:$AJ, 27, FALSE) -> 23.408056 | Z9: =VLOOKUP($A9, RawData!$A:$AJ, 28, FALSE) -> 3.774949 | AA9: =VLOOKUP($A9, RawData!$A:$AJ, 31, FALSE) -> -181.81152 | AB9: =VLOOKUP($A9, RawData!$A:$AJ,32, FALSE) | AC9: =VLOOKUP($A9, RawData!$A:$AJ, 34, FALSE) -> 807.425 | AD9: =VLOOKUP($A9, RawData!$A:$AJ, 35, FALSE) -> 27.02 | AE9: =VLOOKUP($A9, RawData!$A:$AJ, 36, FALSE) -> 32.35
A10: GLAE | B10: GlassBridge Enterprises | C10: Low | D10: [READ PITCH](https://community.microcapclub.com/forums/topic/1324-glassbridge-enterprises-glae/#comment-29369) | E10: =IFERROR(__xludf.DUMMYFUNCTION("IFERROR(HYPERLINK(REGEXEXTRACT(D10,""\(([^)]*)\)""),REGEXEXTRACT(D10,""\[([^\]]+)\]"")),"""") "),"READ PITCH") -> READ PITCH | F10: =VLOOKUP($A10, RawData!$A:$AJ, 33, FALSE) -> 0.7 | G10: =VLOOKUP($A10, RawData!$A:$AJ, 2, FALSE) | H10: =VLOOKUP($A10, RawData!$A:$AJ, 3, FALSE) -> 1 | I10: =VLOOKUP($A10, RawData!$A:$AJ, 4, FALSE) -> 0.14869836 | J10: =VLOOKUP($A10, RawData!$A:$AM, 37, FALSE) -> No data | K10: =VLOOKUP($A10, RawData!$A:$AM, 38, FALSE) | L10: =VLOOKUP($A10, RawData!$A:$AM, 39, FALSE) -> No data | M10: =VLOOKUP($A10, RawData!$A:$AJ, 30, FALSE) | N10: =VLOOKUP($A10, RawData!$A:$AJ, 5, FALSE) -> -133.33333 | O10: =VLOOKUP($A10, RawData!$A:$AJ, 6, FALSE) -> -1.2 | P10: =VLOOKUP($A10, RawData!$A:$AJ, 7, FALSE) | Q10: =VLOOKUP($A10, RawData!$A:$AJ, 8, FALSE) -> 1 | R10: =VLOOKUP($A10, RawData!$A:$AJ, 11, FALSE) | S10: =VLOOKUP($A10, RawData!$A:$AJ, 13, FALSE) -> -3.4 | T10: =VLOOKUP($A10, RawData!$A:$AJ, 14, FALSE) -> 0.8292683 | U10: =VLOOKUP($A10, RawData!$A:$AJ, 23, FALSE) -> -0.2439 | V10: =VLOOKUP($A10, RawData!$A:$AJ, 24, FALSE) | W10: =VLOOKUP($A10, RawData!$A:$AJ, 25, FALSE) | X10: =VLOOKUP($A10, RawData!$A:$AJ, 26, FALSE) | Y10: =VLOOKUP($A10, RawData!$A:$AJ, 27, FALSE) | Z10: =VLOOKUP($A10, RawData!$A:$AJ, 28, FALSE) -> 4.2 | AA10: =VLOOKUP($A10, RawData!$A:$AJ, 31, FALSE) -> -3.7764707 | AB10: =VLOOKUP($A10, RawData!$A:$AJ,32, FALSE) | AC10: =VLOOKUP($A10, RawData!$A:$AJ, 34, FALSE) -> 12.84 | AD10: =VLOOKUP($A10, RawData!$A:$AJ, 35, FALSE) -> 28 | AE10: =VLOOKUP($A10, RawData!$A:$AJ, 36, FALSE) -> 0.03
A11: FC | B11: Franklin Covey | C11: Low | D11: [READ PITCH](https://community.microcapclub.com/forums/topic/4356-franklin-covey-fc/#comment-88993) | E11: =IFERROR(__xludf.DUMMYFUNCTION("IFERROR(HYPERLINK(REGEXEXTRACT(D11,""\(([^)]*)\)""),REGEXEXTRACT(D11,""\[([^\]]+)\]"")),"""") "),"READ PITCH") -> READ PITCH | F11: =VLOOKUP($A11, RawData!$A:$AJ, 33, FALSE) -> 225.53098 | G11: =VLOOKUP($A11, RawData!$A:$AJ, 2, FALSE) | H11: =VLOOKUP($A11, RawData!$A:$AJ, 3, FALSE) -> -0.0899 | I11: =VLOOKUP($A11, RawData!$A:$AJ, 4, FALSE) -> 0.061245136 | J11: =VLOOKUP($A11, RawData!$A:$AM, 37, FALSE) -> 14.162 | K11: =VLOOKUP($A11, RawData!$A:$AM, 38, FALSE) | L11: =VLOOKUP($A11, RawData!$A:$AM, 39, FALSE) -> -0.0015182684 | M11: =VLOOKUP($A11, RawData!$A:$AJ, 30, FALSE) -> 14.923895 | N11: =VLOOKUP($A11, RawData!$A:$AJ, 5, FALSE) -> 0.25230262 | O11: =VLOOKUP($A11, RawData!$A:$AJ, 6, FALSE) -> -0.8689001 | P11: =VLOOKUP($A11, RawData!$A:$AJ, 7, FALSE) | Q11: =VLOOKUP($A11, RawData!$A:$AJ, 8, FALSE) -> 0.7604 | R11: =VLOOKUP($A11, RawData!$A:$AJ, 11, FALSE) | S11: =VLOOKUP($A11, RawData!$A:$AJ, 13, FALSE) -> 13.163 | T11: =VLOOKUP($A11, RawData!$A:$AJ, 14, FALSE) -> 0.26486507 | U11: =VLOOKUP($A11, RawData!$A:$AJ, 23, FALSE) -> -0.0062 | V11: =VLOOKUP($A11, RawData!$A:$AJ, 24, FALSE) | W11: =VLOOKUP($A11, RawData!$A:$AJ, 25, FALSE) | X11: =VLOOKUP($A11, RawData!$A:$AJ, 26, FALSE) -> 78.952805 | Y11: =VLOOKUP($A11, RawData!$A:$AJ, 27, FALSE) -> 58.008152 | Z11: =VLOOKUP($A11, RawData!$A:$AJ, 28, FALSE) -> 0.9069904 | AA11: =VLOOKUP($A11, RawData!$A:$AJ, 31, FALSE) -> 16.056538 | AB11: =VLOOKUP($A11, RawData!$A:$AJ,32, FALSE) | AC11: =VLOOKUP($A11, RawData!$A:$AJ, 34, FALSE) -> 211.3522 | AD11: =VLOOKUP($A11, RawData!$A:$AJ, 35, FALSE) -> 19.92 | AE11: =VLOOKUP($A11, RawData!$A:$AJ, 36, FALSE) -> 12.16
A12: AVNW | B12: Aviat Networks | C12: Lowest | D12: [READ PITCH](https://community.microcapclub.com/forums/topic/3390-aviat-networks-avnw/#comment-75905) | E12: =IFERROR(__xludf.DUMMYFUNCTION("IFERROR(HYPERLINK(REGEXEXTRACT(D12,""\(([^)]*)\)""),REGEXEXTRACT(D12,""\[([^\]]+)\]"")),"""") "),"READ PITCH") -> READ PITCH | F12: =VLOOKUP($A12, RawData!$A:$AJ, 33, FALSE) -> 274.66278 | G12: =VLOOKUP($A12, RawData!$A:$AJ, 2, FALSE) | H12: =VLOOKUP($A12, RawData!$A:$AJ, 3, FALSE) -> 0.1089 | I12: =VLOOKUP($A12, RawData!$A:$AJ, 4, FALSE) -> 0.12976143 | J12: =VLOOKUP($A12, RawData!$A:$AM, 37, FALSE) -> 40.438 | K12: =VLOOKUP($A12, RawData!$A:$AM, 38, FALSE) | L12: =VLOOKUP($A12, RawData!$A:$AM, 39, FALSE) -> 0.25286326 | M12: =VLOOKUP($A12, RawData!$A:$AJ, 30, FALSE) -> 7.9107966 | N12: =VLOOKUP($A12, RawData!$A:$AJ, 5, FALSE) -> 1.0422119 | O12: =VLOOKUP($A12, RawData!$A:$AJ, 6, FALSE) -> -3.6116316 | P12: =VLOOKUP($A12, RawData!$A:$AJ, 7, FALSE) | Q12: =VLOOKUP($A12, RawData!$A:$AJ, 8, FALSE) -> 0.3425 | R12: =VLOOKUP($A12, RawData!$A:$AJ, 11, FALSE) | S12: =VLOOKUP($A12, RawData!$A:$AJ, 13, FALSE) -> 11.868 | T12: =VLOOKUP($A12, RawData!$A:$AJ, 14, FALSE) -> -0.17378317 | U12: =VLOOKUP($A12, RawData!$A:$AJ, 23, FALSE) -> 0.0214 | V12: =VLOOKUP($A12, RawData!$A:$AJ, 24, FALSE) | W12: =VLOOKUP($A12, RawData!$A:$AJ, 25, FALSE) | X12: =VLOOKUP($A12, RawData!$A:$AJ, 26, FALSE) -> 20.792318 | Y12: =VLOOKUP($A12, RawData!$A:$AJ, 27, FALSE) -> 8.618701 | Z12: =VLOOKUP($A12, RawData!$A:$AJ, 28, FALSE) -> 0.61354935 | AA12: =VLOOKUP($A12, RawData!$A:$AJ, 31, FALSE) -> 26.954567 | AB12: =VLOOKUP($A12, RawData!$A:$AJ,32, FALSE) | AC12: =VLOOKUP($A12, RawData!$A:$AJ, 34, FALSE) -> 319.8968 | AD12: =VLOOKUP($A12, RawData!$A:$AJ, 35, FALSE) -> 21.67 | AE12: =VLOOKUP($A12, RawData!$A:$AJ, 36, FALSE) -> 12.84
A13: CCRD | B13: CoreCard | C13: Medium High | D13: [READ PITCH](https://community.microcapclub.com/forums/topic/2329-corecard-corporation-ccrd/#comment-54126) | E13: =IFERROR(__xludf.DUMMYFUNCTION("IFERROR(HYPERLINK(REGEXEXTRACT(D13,""\(([^)]*)\)""),REGEXEXTRACT(D13,""\[([^\]]+)\]"")),"""") "),"READ PITCH") -> READ PITCH | F13: =VLOOKUP($A13, RawData!$A:$AJ, 33, FALSE) -> 183.9 | G13: =VLOOKUP($A13, RawData!$A:$AJ, 2, FALSE) | H13: =VLOOKUP($A13, RawData!$A:$AJ, 3, FALSE) -> 0.2361 | I13: =VLOOKUP($A13, RawData!$A:$AJ, 4, FALSE) -> 0.1262796 | J13: =VLOOKUP($A13, RawData!$A:$AM, 37, FALSE) -> 14.139 | K13: =VLOOKUP($A13, RawData!$A:$AM, 38, FALSE) | L13: =VLOOKUP($A13, RawData!$A:$AM, 39, FALSE) -> 0.008844381 | M13: =VLOOKUP($A13, RawData!$A:$AJ, 30, FALSE) -> 11.885643 | N13: =VLOOKUP($A13, RawData!$A:$AJ, 5, FALSE) -> 1.028498 | O13: =VLOOKUP($A13, RawData!$A:$AJ, 6, FALSE) -> 4.0326633 | P13: =VLOOKUP($A13, RawData!$A:$AJ, 7, FALSE) | Q13: =VLOOKUP($A13, RawData!$A:$AJ, 8, FALSE) -> 0.4541 | R13: =VLOOKUP($A13, RawData!$A:$AJ, 11, FALSE) | S13: =VLOOKUP($A13, RawData!$A:$AJ, 13, FALSE) -> 8.916 | T13: =VLOOKUP($A13, RawData!$A:$AJ, 14, FALSE) -> 207.34883 | U13: =VLOOKUP($A13, RawData!$A:$AJ, 23, FALSE) -> 0.123 | V13: =VLOOKUP($A13, RawData!$A:$AJ, 24, FALSE) | W13: =VLOOKUP($A13, RawData!$A:$AJ, 25, FALSE) | X13: =VLOOKUP($A13, RawData!$A:$AJ, 26, FALSE) -> 24.297565 | Y13: =VLOOKUP($A13, RawData!$A:$AJ, 27, FALSE) -> 22.272728 | Z13: =VLOOKUP($A13, RawData!$A:$AJ, 28, FALSE) -> 3.0038283 | AA13: =VLOOKUP($A13, RawData!$A:$AJ, 31, FALSE) -> 18.84826 | AB13: =VLOOKUP($A13, RawData!$A:$AJ,32, FALSE) | AC13: =VLOOKUP($A13, RawData!$A:$AJ, 34, FALSE) -> 168.0511 | AD13: =VLOOKUP($A13, RawData!$A:$AJ, 35, FALSE) -> 23.6 | AE13: =VLOOKUP($A13, RawData!$A:$AJ, 36, FALSE) -> 7.79
A14: ACFN | B14: Acorn Energy | C14: High | D14: [READ PITCH](https://community.microcapclub.com/forums/topic/4634-acorn-energy-inc-acfn/) | E14: =IFERROR(__xludf.DUMMYFUNCTION("IFERROR(HYPERLINK(REGEXEXTRACT(D14,""\(([^)]*)\)""),REGEXEXTRACT(D14,""\[([^\]]+)\]"")),"""") "),"READ PITCH") -> READ PITCH | F14: =VLOOKUP($A14, RawData!$A:$AJ, 33, FALSE) -> 51.26969 | G14: =VLOOKUP($A14, RawData!$A:$AJ, 2, FALSE) | H14: =VLOOKUP($A14, RawData!$A:$AJ, 3, FALSE) -> 0.363 | I14: =VLOOKUP($A14, RawData!$A:$AJ, 4, FALSE) -> 0.1484058 | J14: =VLOOKUP($A14, RawData!$A:$AM, 37, FALSE) -> 2.058 | K14: =VLOOKUP($A14, RawData!$A:$AM, 38, FALSE) | L14: =VLOOKUP($A14, RawData!$A:$AM, 39, FALSE) -> -0.4104765 | M14: =VLOOKUP($A14, RawData!$A:$AJ, 30, FALSE) -> 23.335278 | N14: =VLOOKUP($A14, RawData!$A:$AJ, 5, FALSE) -> 2.5176 | O14: =VLOOKUP($A14, RawData!$A:$AJ, 6, FALSE) -> 54.210526 | P14: =VLOOKUP($A14, RawData!$A:$AJ, 7, FALSE) | Q14: =VLOOKUP($A14, RawData!$A:$AJ, 8, FALSE) -> 0.7281 | R14: =VLOOKUP($A14, RawData!$A:$AJ, 11, FALSE) | S14: =VLOOKUP($A14, RawData!$A:$AJ, 13, FALSE) -> 0.849 | T14: =VLOOKUP($A14, RawData!$A:$AJ, 14, FALSE) -> -141.5 | U14: =VLOOKUP($A14, RawData!$A:$AJ, 23, FALSE) -> 0.5661 | V14: =VLOOKUP($A14, RawData!$A:$AJ, 24, FALSE) | W14: =VLOOKUP($A14, RawData!$A:$AJ, 25, FALSE) | X14: =VLOOKUP($A14, RawData!$A:$AJ, 26, FALSE) -> 7.9996824 | Y14: =VLOOKUP($A14, RawData!$A:$AJ, 27, FALSE) | Z14: =VLOOKUP($A14, RawData!$A:$AJ, 28, FALSE) -> 4.5831056 | AA14: =VLOOKUP($A14, RawData!$A:$AJ, 31, FALSE) -> 56.565372 | AB14: =VLOOKUP($A14, RawData!$A:$AJ,32, FALSE) | AC14: =VLOOKUP($A14, RawData!$A:$AJ, 34, FALSE) -> 48.024 | AD14: =VLOOKUP($A14, RawData!$A:$AJ, 35, FALSE) -> 20.14 | AE14: =VLOOKUP($A14, RawData!$A:$AJ, 36, FALSE) -> 2.5
A15: TSAT | B15: Telesat | C15: Low | D15: [READ PITCH](https://community.microcapclub.com/forums/topic/3887-telesat-corporation-tsat/#comment-83043) | E15: =IFERROR(__xludf.DUMMYFUNCTION("IFERROR(HYPERLINK(REGEXEXTRACT(D15,""\(([^)]*)\)""),REGEXEXTRACT(D15,""\[([^\]]+)\]"")),"""") "),"READ PITCH") -> READ PITCH | F15: =VLOOKUP($A15, RawData!$A:$AJ, 33, FALSE) -> 474.00955 | G15: =VLOOKUP($A15, RawData!$A:$AJ, 2, FALSE) | H15: =VLOOKUP($A15, RawData!$A:$AJ, 3, FALSE) -> -0.2579 | I15: =VLOOKUP($A15, RawData!$A:$AJ, 4, FALSE) -> -0.12115695 | J15: =VLOOKUP($A15, RawData!$A:$AM, 37, FALSE) -> 21.358 | K15: =VLOOKUP($A15, RawData!$A:$AM, 38, FALSE) | L15: =VLOOKUP($A15, RawData!$A:$AM, 39, FALSE) -> -0.5451669 | M15: =VLOOKUP($A15, RawData!$A:$AJ, 30, FALSE) -> 163.88249 | N15: =VLOOKUP($A15, RawData!$A:$AJ, 5, FALSE) -> -3.055823 | O15: =VLOOKUP($A15, RawData!$A:$AJ, 6, FALSE) -> -4.2065806 | P15: =VLOOKUP($A15, RawData!$A:$AJ, 7, FALSE) | Q15: =VLOOKUP($A15, RawData!$A:$AJ, 8, FALSE) -> 0.9429 | R15: =VLOOKUP($A15, RawData!$A:$AJ, 11, FALSE) | S15: =VLOOKUP($A15, RawData!$A:$AJ, 13, FALSE) -> -1009.604 | T15: =VLOOKUP($A15, RawData!$A:$AJ, 14, FALSE) -> 1.9206115 | U15: =VLOOKUP($A15, RawData!$A:$AJ, 23, FALSE) -> -0.0225 | V15: =VLOOKUP($A15, RawData!$A:$AJ, 24, FALSE) | W15: =VLOOKUP($A15, RawData!$A:$AJ, 25, FALSE) | X15: =VLOOKUP($A15, RawData!$A:$AJ, 26, FALSE) | Y15: =VLOOKUP($A15, RawData!$A:$AJ, 27, FALSE) | Z15: =VLOOKUP($A15, RawData!$A:$AJ, 28, FALSE) -> 1.4564012 | AA15: =VLOOKUP($A15, RawData!$A:$AJ, 31, FALSE) -> -3.46692 | AB15: =VLOOKUP($A15, RawData!$A:$AJ,32, FALSE) | AC15: =VLOOKUP($A15, RawData!$A:$AJ, 34, FALSE) -> 2520.8516 | AD15: =VLOOKUP($A15, RawData!$A:$AJ, 35, FALSE) -> 33.78 | AE15: =VLOOKUP($A15, RawData!$A:$AJ, 36, FALSE) -> 51.09
A16: CSPI | B16: CSP Inc. | C16: Medium | D16: [READ PITCH](https://community.microcapclub.com/forums/topic/4176-csp-inc-cspi/#comment-86378) | E16: =IFERROR(__xludf.DUMMYFUNCTION("IFERROR(HYPERLINK(REGEXEXTRACT(D16,""\(([^)]*)\)""),REGEXEXTRACT(D16,""\[([^\]]+)\]"")),"""") "),"READ PITCH") -> READ PITCH | F16: =VLOOKUP($A16, RawData!$A:$AJ, 33, FALSE) -> 114.54882 | G16: =VLOOKUP($A16, RawData!$A:$AJ, 2, FALSE) | H16: =VLOOKUP($A16, RawData!$A:$AJ, 3, FALSE) -> -0.2162 | I16: =VLOOKUP($A16, RawData!$A:$AJ, 4, FALSE) -> -0.07033556 | J16: =VLOOKUP($A16, RawData!$A:$AM, 37, FALSE) -> -2.94 | K16: =VLOOKUP($A16, RawData!$A:$AM, 38, FALSE) | L16: =VLOOKUP($A16, RawData!$A:$AM, 39, FALSE) -> 0.26239598 | M16: =VLOOKUP($A16, RawData!$A:$AJ, 30, FALSE) -> -30.354218 | N16: =VLOOKUP($A16, RawData!$A:$AJ, 5, FALSE) -> -0.009229209 | O16: =VLOOKUP($A16, RawData!$A:$AJ, 6, FALSE) -> -0.7283582 | P16: =VLOOKUP($A16, RawData!$A:$AJ, 7, FALSE) | Q16: =VLOOKUP($A16, RawData!$A:$AJ, 8, FALSE) -> 0.3248 | R16: =VLOOKUP($A16, RawData!$A:$AJ, 11, FALSE) | S16: =VLOOKUP($A16, RawData!$A:$AJ, 13, FALSE) -> 1.894 | T16: =VLOOKUP($A16, RawData!$A:$AJ, 14, FALSE) -> 0.4735 | U16: =VLOOKUP($A16, RawData!$A:$AJ, 23, FALSE) -> -0.0013 | V16: =VLOOKUP($A16, RawData!$A:$AJ, 24, FALSE) | W16: =VLOOKUP($A16, RawData!$A:$AJ, 25, FALSE) | X16: =VLOOKUP($A16, RawData!$A:$AJ, 26, FALSE) | Y16: =VLOOKUP($A16, RawData!$A:$AJ, 27, FALSE) -> No data | Z16: =VLOOKUP($A16, RawData!$A:$AJ, 28, FALSE) -> 2.6744697 | AA16: =VLOOKUP($A16, RawData!$A:$AJ, 31, FALSE) -> 47.11795 | AB16: =VLOOKUP($A16, RawData!$A:$AJ,32, FALSE) | AC16: =VLOOKUP($A16, RawData!$A:$AJ, 34, FALSE) -> 89.2414 | AD16: =VLOOKUP($A16, RawData!$A:$AJ, 35, FALSE) -> 11.74 | AE16: =VLOOKUP($A16, RawData!$A:$AJ, 36, FALSE) -> 9.86
A17: SPOK | B17: Spok Holdings | C17: Low | D17: [READ PITCH](https://community.microcapclub.com/forums/topic/3683-spok-holdings-spok/#comment-80588) | E17: =IFERROR(__xludf.DUMMYFUNCTION("IFERROR(HYPERLINK(REGEXEXTRACT(D17,""\(([^)]*)\)""),REGEXEXTRACT(D17,""\[([^\]]+)\]"")),"""") "),"READ PITCH") -> READ PITCH | F17: =VLOOKUP($A17, RawData!$A:$AJ, 33, FALSE) -> 268.31177 | G17: =VLOOKUP($A17, RawData!$A:$AJ, 2, FALSE) | H17: =VLOOKUP($A17, RawData!$A:$AJ, 3, FALSE) -> 0.0147 | I17: =VLOOKUP($A17, RawData!$A:$AJ, 4, FALSE) -> -0.014334536 | J17: =VLOOKUP($A17, RawData!$A:$AM, 37, FALSE) -> 24.705 | K17: =VLOOKUP($A17, RawData!$A:$AM, 38, FALSE) | L17: =VLOOKUP($A17, RawData!$A:$AM, 39, FALSE) -> 0.3226834 | M17: =VLOOKUP($A17, RawData!$A:$AJ, 30, FALSE) -> 10.174661 | N17: =VLOOKUP($A17, RawData!$A:$AJ, 5, FALSE) -> 0.8055825 | O17: =VLOOKUP($A17, RawData!$A:$AJ, 6, FALSE) -> 0.12998775 | P17: =VLOOKUP($A17, RawData!$A:$AJ, 7, FALSE) | Q17: =VLOOKUP($A17, RawData!$A:$AJ, 8, FALSE) -> 0.6274 | R17: =VLOOKUP($A17, RawData!$A:$AJ, 11, FALSE) | S17: =VLOOKUP($A17, RawData!$A:$AJ, 13, FALSE) -> 22.623 | T17: =VLOOKUP($A17, RawData!$A:$AJ, 14, FALSE) -> 0.7818829 | U17: =VLOOKUP($A17, RawData!$A:$AJ, 23, FALSE) -> 0.079 | V17: =VLOOKUP($A17, RawData!$A:$AJ, 24, FALSE) | W17: =VLOOKUP($A17, RawData!$A:$AJ, 25, FALSE) | X17: =VLOOKUP($A17, RawData!$A:$AJ, 26, FALSE) -> 16.435312 | Y17: =VLOOKUP($A17, RawData!$A:$AJ, 27, FALSE) -> 16.22549 | Z17: =VLOOKUP($A17, RawData!$A:$AJ, 28, FALSE) -> 1.9518101 | AA17: =VLOOKUP($A17, RawData!$A:$AJ, 31, FALSE) -> 11.111037 | AB17: =VLOOKUP($A17, RawData!$A:$AJ,32, FALSE) | AC17: =VLOOKUP($A17, RawData!$A:$AJ, 34, FALSE) -> 251.365 | AD17: =VLOOKUP($A17, RawData!$A:$AJ, 35, FALSE) -> 13.24 | AE17: =VLOOKUP($A17, RawData!$A:$AJ, 36, FALSE) -> 20.6
A18: SILC | B18: Silicom | C18: Low | D18: [READ PITCH](https://community.microcapclub.com/forums/topic/1454-silicom-silc/#comment-31959) | E18: =IFERROR(__xludf.DUMMYFUNCTION("IFERROR(HYPERLINK(REGEXEXTRACT(D18,""\(([^)]*)\)""),REGEXEXTRACT(D18,""\[([^\]]+)\]"")),"""") "),"READ PITCH") -> READ PITCH | F18: =VLOOKUP($A18, RawData!$A:$AJ, 33, FALSE) -> 88.98035 | G18: =VLOOKUP($A18, RawData!$A:$AJ, 2, FALSE) | H18: =VLOOKUP($A18, RawData!$A:$AJ, 3, FALSE) -> -0.4262 | I18: =VLOOKUP($A18, RawData!$A:$AJ, 4, FALSE) -> -0.022336941 | J18: =VLOOKUP($A18, RawData!$A:$AM, 37, FALSE) -> 0 | K18: =VLOOKUP($A18, RawData!$A:$AM, 38, FALSE) | L18: =VLOOKUP($A18, RawData!$A:$AM, 39, FALSE) -> -0.22127618 | M18: =VLOOKUP($A18, RawData!$A:$AJ, 30, FALSE) | N18: =VLOOKUP($A18, RawData!$A:$AJ, 5, FALSE) -> 0 | O18: =VLOOKUP($A18, RawData!$A:$AJ, 6, FALSE) -> -1.1495436 | P18: =VLOOKUP($A18, RawData!$A:$AJ, 7, FALSE) | Q18: =VLOOKUP($A18, RawData!$A:$AJ, 8, FALSE) -> 0.2896 | R18: =VLOOKUP($A18, RawData!$A:$AJ, 11, FALSE) | S18: =VLOOKUP($A18, RawData!$A:$AJ, 13, FALSE) -> 0 | T18: =VLOOKUP($A18, RawData!$A:$AJ, 14, FALSE) -> 17.513794 | U18: =VLOOKUP($A18, RawData!$A:$AJ, 23, FALSE) -> -0.0984 | V18: =VLOOKUP($A18, RawData!$A:$AJ, 24, FALSE) | W18: =VLOOKUP($A18, RawData!$A:$AJ, 25, FALSE) | X18: =VLOOKUP($A18, RawData!$A:$AJ, 26, FALSE) | Y18: =VLOOKUP($A18, RawData!$A:$AJ, 27, FALSE) | Z18: =VLOOKUP($A18, RawData!$A:$AJ, 28, FALSE) -> 1.4409026 | AA18: =VLOOKUP($A18, RawData!$A:$AJ, 31, FALSE) | AB18: =VLOOKUP($A18, RawData!$A:$AJ,32, FALSE) | AC18: =VLOOKUP($A18, RawData!$A:$AJ, 34, FALSE) -> 84.483 | AD18: =VLOOKUP($A18, RawData!$A:$AJ, 35, FALSE) -> 14.9 | AE18: =VLOOKUP($A18, RawData!$A:$AJ, 36, FALSE) -> 5.67
A19: SODI | B19: Solitron Devices | C19: Medium | D19: [READ PITCH](https://community.microcapclub.com/forums/topic/2871-solitron-devices-sodi/#comment-66366) | E19: =IFERROR(__xludf.DUMMYFUNCTION("IFERROR(HYPERLINK(REGEXEXTRACT(D19,""\(([^)]*)\)""),REGEXEXTRACT(D19,""\[([^\]]+)\]"")),"""") "),"READ PITCH") -> READ PITCH | F19: =VLOOKUP($A19, RawData!$A:$AJ, 33, FALSE) -> 39.761353 | G19: =VLOOKUP($A19, RawData!$A:$AJ, 2, FALSE) | H19: =VLOOKUP($A19, RawData!$A:$AJ, 3, FALSE) -> -0.1594 | I19: =VLOOKUP($A19, RawData!$A:$AJ, 4, FALSE) -> 0.05985148 | J19: =VLOOKUP($A19, RawData!$A:$AM, 37, FALSE) -> 0.479 | K19: =VLOOKUP($A19, RawData!$A:$AM, 38, FALSE) | L19: =VLOOKUP($A19, RawData!$A:$AM, 39, FALSE) -> -0.14264044 | M19: =VLOOKUP($A19, RawData!$A:$AJ, 30, FALSE) -> 89.98852 | N19: =VLOOKUP($A19, RawData!$A:$AJ, 5, FALSE) -> -0.17272727 | O19: =VLOOKUP($A19, RawData!$A:$AJ, 6, FALSE) -> -1.0566008 | P19: =VLOOKUP($A19, RawData!$A:$AJ, 7, FALSE) | Q19: =VLOOKUP($A19, RawData!$A:$AJ, 8, FALSE) -> 0.2126 | R19: =VLOOKUP($A19, RawData!$A:$AJ, 11, FALSE) | S19: =VLOOKUP($A19, RawData!$A:$AJ, 13, FALSE) -> 1.472 | T19: =VLOOKUP($A19, RawData!$A:$AJ, 14, FALSE) -> 3.0413222 | U19: =VLOOKUP($A19, RawData!$A:$AJ, 23, FALSE) -> -0.0148 | V19: =VLOOKUP($A19, RawData!$A:$AJ, 24, FALSE) | W19: =VLOOKUP($A19, RawData!$A:$AJ, 25, FALSE) | X19: =VLOOKUP($A19, RawData!$A:$AJ, 26, FALSE) | Y19: =VLOOKUP($A19, RawData!$A:$AJ, 27, FALSE) -> No data | Z19: =VLOOKUP($A19, RawData!$A:$AJ, 28, FALSE) -> 3.1935618 | AA19: =VLOOKUP($A19, RawData!$A:$AJ, 31, FALSE) -> 29.282948 | AB19: =VLOOKUP($A19, RawData!$A:$AJ,32, FALSE) | AC19: =VLOOKUP($A19, RawData!$A:$AJ, 34, FALSE) -> 43.1045 | AD19: =VLOOKUP($A19, RawData!$A:$AJ, 35, FALSE) -> 21 | AE19: =VLOOKUP($A19, RawData!$A:$AJ, 36, FALSE) -> 2.09
A20: THRY | B20: Thryv Holdings, Inc. | C20: Medium | D20: [READ PITCH](https://community.microcapclub.com/forums/topic/5021-thryv-holdings-inc-thry/#comment-97946) | E20: =IFERROR(__xludf.DUMMYFUNCTION("IFERROR(HYPERLINK(REGEXEXTRACT(D20,""\(([^)]*)\)""),REGEXEXTRACT(D20,""\[([^\]]+)\]"")),"""") "),"READ PITCH") -> READ PITCH | F20: =VLOOKUP($A20, RawData!$A:$AJ, 33, FALSE) -> 241.41597 | G20: =VLOOKUP($A20, RawData!$A:$AJ, 2, FALSE) | H20: =VLOOKUP($A20, RawData!$A:$AJ, 3, FALSE) -> -0.1073 | I20: =VLOOKUP($A20, RawData!$A:$AJ, 4, FALSE) -> -0.019909434 | J20: =VLOOKUP($A20, RawData!$A:$AM, 37, FALSE) -> 110.116 | K20: =VLOOKUP($A20, RawData!$A:$AM, 38, FALSE) | L20: =VLOOKUP($A20, RawData!$A:$AM, 39, FALSE) -> -0.18989244 | M20: =VLOOKUP($A20, RawData!$A:$AJ, 30, FALSE) -> 4.503289 | N20: =VLOOKUP($A20, RawData!$A:$AJ, 5, FALSE) -> 0.40959156 | O20: =VLOOKUP($A20, RawData!$A:$AJ, 6, FALSE) -> -1.0525557 | P20: =VLOOKUP($A20, RawData!$A:$AJ, 7, FALSE) | Q20: =VLOOKUP($A20, RawData!$A:$AJ, 8, FALSE) -> 0.6736 | R20: =VLOOKUP($A20, RawData!$A:$AJ, 11, FALSE) | S20: =VLOOKUP($A20, RawData!$A:$AJ, 13, FALSE) -> 36.166 | T20: =VLOOKUP($A20, RawData!$A:$AJ, 14, FALSE) -> 0.49513978 | U20: =VLOOKUP($A20, RawData!$A:$AJ, 23, FALSE) -> 0.0255 | V20: =VLOOKUP($A20, RawData!$A:$AJ, 24, FALSE) | W20: =VLOOKUP($A20, RawData!$A:$AJ, 25, FALSE) | X20: =VLOOKUP($A20, RawData!$A:$AJ, 26, FALSE) -> 13.403597 | Y20: =VLOOKUP($A20, RawData!$A:$AJ, 27, FALSE) -> 10.574368 | Z20: =VLOOKUP($A20, RawData!$A:$AJ, 28, FALSE) -> 0.3067393 | AA20: =VLOOKUP($A20, RawData!$A:$AJ, 31, FALSE) -> 13.711337 | AB20: =VLOOKUP($A20, RawData!$A:$AJ,32, FALSE) | AC20: =VLOOKUP($A20, RawData!$A:$AJ, 34, FALSE) -> 495.8842 | AD20: =VLOOKUP($A20, RawData!$A:$AJ, 35, FALSE) -> 5.49 | AE20: =VLOOKUP($A20, RawData!$A:$AJ, 36, FALSE) -> 43.58
A21: GAMB | B21: Gambling.com Group Ltd | C21: Low | D21: [READ PITCH](https://community.microcapclub.com/forums/topic/4512-gamblingcom-group-ltd-gamb/#comment-91092) | E21: =IFERROR(__xludf.DUMMYFUNCTION("IFERROR(HYPERLINK(REGEXEXTRACT(D21,""\(([^)]*)\)""),REGEXEXTRACT(D21,""\[([^\]]+)\]"")),"""") "),"READ PITCH") -> READ PITCH | F21: =VLOOKUP($A21, RawData!$A:$AJ, 33, FALSE) -> 185.49243 | G21: =VLOOKUP($A21, RawData!$A:$AJ, 2, FALSE) | H21: =VLOOKUP($A21, RawData!$A:$AJ, 3, FALSE) -> 0.2421 | I21: =VLOOKUP($A21, RawData!$A:$AJ, 4, FALSE) -> 0.38248485 | J21: =VLOOKUP($A21, RawData!$A:$AM, 37, FALSE) -> 13.447 | K21: =VLOOKUP($A21, RawData!$A:$AM, 38, FALSE) | L21: =VLOOKUP($A21, RawData!$A:$AM, 39, FALSE) -> -0.056652006 | M21: =VLOOKUP($A21, RawData!$A:$AJ, 30, FALSE) -> 19.141623 | N21: =VLOOKUP($A21, RawData!$A:$AJ, 5, FALSE) -> 0.053852715 | O21: =VLOOKUP($A21, RawData!$A:$AJ, 6, FALSE) -> -0.9479942 | P21: =VLOOKUP($A21, RawData!$A:$AJ, 7, FALSE) | Q21: =VLOOKUP($A21, RawData!$A:$AJ, 8, FALSE) -> 0.9317 | R21: =VLOOKUP($A21, RawData!$A:$AJ, 11, FALSE) | S21: =VLOOKUP($A21, RawData!$A:$AJ, 13, FALSE) -> 41.879 | T21: =VLOOKUP($A21, RawData!$A:$AJ, 14, FALSE) -> 26.966516 | U21: =VLOOKUP($A21, RawData!$A:$AJ, 23, FALSE) -> 0.0069 | V21: =VLOOKUP($A21, RawData!$A:$AJ, 24, FALSE) | W21: =VLOOKUP($A21, RawData!$A:$AJ, 25, FALSE) | X21: =VLOOKUP($A21, RawData!$A:$AJ, 26, FALSE) -> 93.21721 | Y21: =VLOOKUP($A21, RawData!$A:$AJ, 27, FALSE) | Z21: =VLOOKUP($A21, RawData!$A:$AJ, 28, FALSE) -> 1.1425999 | AA21: =VLOOKUP($A21, RawData!$A:$AJ, 31, FALSE) -> 6.1462164 | AB21: =VLOOKUP($A21, RawData!$A:$AJ,32, FALSE) | AC21: =VLOOKUP($A21, RawData!$A:$AJ, 34, FALSE) -> 257.3974 | AD21: =VLOOKUP($A21, RawData!$A:$AJ, 35, FALSE) -> 5.02 | AE21: =VLOOKUP($A21, RawData!$A:$AJ, 36, FALSE) -> 35.17
